2020-07-15 10:17:22,736 INFO [root] [test_publish_article.py(test_login:32)] - 用例的数据如下：用户名：13012345678， 验证码：246810， 预期结果：test123
2020-07-15 10:52:08,076 INFO [root] [test_publish_article.py(test_login:32)] - 用例的数据如下：用户名：13012345678， 验证码：246810， 预期结果：test123
2020-07-15 14:45:14,014 INFO [selenium.webdriver.remote.remote_connection] [remote_connection.py(__init__:117)] - Could not connect to port 4723 on host 127.0.0.1
2020-07-15 14:45:14,014 INFO [selenium.webdriver.remote.remote_connection] [remote_connection.py(__init__:136)] - Could not get IP address for host: 127.0.0.1
2020-07-15 14:45:16,019 WARNING [urllib3.connectionpool] [connectionpool.py(urlopen:750)] - Retrying (Retry(total=2, connect=None, read=None, redirect=None, status=None)) after connection broken by 'NewConnectionError('<urllib3.connection.HTTPConnection object at 0x000001F9DB5DC278>: Failed to establish a new connection: [WinError 10061] 由于目标计算机积极拒绝，无法连接。',)': /wd/hub/session
2020-07-15 14:45:18,023 WARNING [urllib3.connectionpool] [connectionpool.py(urlopen:750)] - Retrying (Retry(total=1, connect=None, read=None, redirect=None, status=None)) after connection broken by 'NewConnectionError('<urllib3.connection.HTTPConnection object at 0x000001F9DB5DCEB8>: Failed to establish a new connection: [WinError 10061] 由于目标计算机积极拒绝，无法连接。',)': /wd/hub/session
2020-07-15 14:45:20,027 WARNING [urllib3.connectionpool] [connectionpool.py(urlopen:750)] - Retrying (Retry(total=0, connect=None, read=None, redirect=None, status=None)) after connection broken by 'NewConnectionError('<urllib3.connection.HTTPConnection object at 0x000001F9DB5DCC50>: Failed to establish a new connection: [WinError 10061] 由于目标计算机积极拒绝，无法连接。',)': /wd/hub/session
2020-07-15 14:45:30,998 INFO [root] [test_publish_article.py(test_login:32)] - 用例的数据如下：用户名：13012345678， 验证码：246810， 预期结果：test123
2020-07-15 14:46:04,788 INFO [selenium.webdriver.remote.remote_connection] [remote_connection.py(__init__:117)] - Could not connect to port 4723 on host 127.0.0.1
2020-07-15 14:46:04,788 INFO [selenium.webdriver.remote.remote_connection] [remote_connection.py(__init__:136)] - Could not get IP address for host: 127.0.0.1
2020-07-15 14:46:06,791 WARNING [urllib3.connectionpool] [connectionpool.py(urlopen:750)] - Retrying (Retry(total=2, connect=None, read=None, redirect=None, status=None)) after connection broken by 'NewConnectionError('<urllib3.connection.HTTPConnection object at 0x00000265530AF9B0>: Failed to establish a new connection: [WinError 10061] 由于目标计算机积极拒绝，无法连接。',)': /wd/hub/session
2020-07-15 14:46:08,795 WARNING [urllib3.connectionpool] [connectionpool.py(urlopen:750)] - Retrying (Retry(total=1, connect=None, read=None, redirect=None, status=None)) after connection broken by 'NewConnectionError('<urllib3.connection.HTTPConnection object at 0x000002655485E128>: Failed to establish a new connection: [WinError 10061] 由于目标计算机积极拒绝，无法连接。',)': /wd/hub/session
2020-07-15 14:46:10,798 WARNING [urllib3.connectionpool] [connectionpool.py(urlopen:750)] - Retrying (Retry(total=0, connect=None, read=None, redirect=None, status=None)) after connection broken by 'NewConnectionError('<urllib3.connection.HTTPConnection object at 0x000002655485E3C8>: Failed to establish a new connection: [WinError 10061] 由于目标计算机积极拒绝，无法连接。',)': /wd/hub/session
2020-07-15 17:19:50,780 INFO [root] [test_publish_article.py(test_login:32)] - 用例的数据如下：用户名：13012345678， 验证码：246810， 预期结果：test123
2020-07-15 17:42:35,030 INFO [root] [test_publish_article.py(test_login:32)] - 用例的数据如下：用户名：13012345678， 验证码：246810， 预期结果：test123
